{
 "cells": [
  {
   "cell_type": "code",
   "execution_count": 1,
   "id": "0a70d56a",
   "metadata": {},
   "outputs": [],
   "source": [
    "import syft as sy"
   ]
  },
  {
   "cell_type": "code",
   "execution_count": 2,
   "id": "2717ab39",
   "metadata": {},
   "outputs": [
    {
     "name": "stdout",
     "output_type": "stream",
     "text": [
      "🎤  🎸  ♪♪♪ Starting Duet ♫♫♫  🎻  🎹\n",
      "\n",
      "♫♫♫ >\u001b[93m DISCLAIMER\u001b[0m: \u001b[1mDuet is an experimental feature currently in beta.\n",
      "♫♫♫ > Use at your own risk.\n",
      "\u001b[0m\n",
      "\u001b[1m\n",
      "    > ❤️ \u001b[91mLove\u001b[0m \u001b[92mDuet\u001b[0m? \u001b[93mPlease\u001b[0m \u001b[94mconsider\u001b[0m \u001b[95msupporting\u001b[0m \u001b[91mour\u001b[0m \u001b[93mcommunity!\u001b[0m\n",
      "    > https://github.com/sponsors/OpenMined\u001b[1m\n",
      "\n",
      "♫♫♫ > Punching through firewall to OpenGrid Network Node at:\n",
      "♫♫♫ > http://ec2-18-218-7-180.us-east-2.compute.amazonaws.com:5000\n",
      "♫♫♫ >\n",
      "♫♫♫ > ...waiting for response from OpenGrid Network... \n",
      "♫♫♫ > \u001b[92mDONE!\u001b[0m\n",
      "\n",
      "♫♫♫ > \u001b[95mSTEP 1:\u001b[0m Send the following code to your Duet Partner!\n",
      "\n",
      "import syft as sy\n",
      "duet = sy.join_duet(loopback=True)\n",
      "\n",
      "♫♫♫ > Connecting...\n",
      "\n",
      "♫♫♫ > \u001b[92mCONNECTED!\u001b[0m\n",
      "\n",
      "`searchable` is deprecated please use `pointable` in futurees: 0  Request Handlers: 0                                \n",
      "♫♫♫ > DUET LIVE STATUS  *  Objects: 7  Requests: 0   Messages: 6249  Request Handlers: 1                                \r"
     ]
    }
   ],
   "source": [
    "duet = sy.launch_duet(loopback=True)"
   ]
  },
  {
   "cell_type": "code",
   "execution_count": 3,
   "id": "bff2e1bc",
   "metadata": {},
   "outputs": [
    {
     "name": "stdout",
     "output_type": "stream",
     "text": [
      "♫♫♫ > DUET LIVE STATUS  -  Objects: 0  Requests: 0   Messages: 0  Request Handlers: 0                                \r"
     ]
    }
   ],
   "source": [
    "from sklearn import datasets"
   ]
  },
  {
   "cell_type": "code",
   "execution_count": 20,
   "id": "ce75c5e3",
   "metadata": {
    "scrolled": false
   },
   "outputs": [],
   "source": [
    "X,y= datasets.load_digits()[\"data\"],datasets.load_digits()[\"target\"] "
   ]
  },
  {
   "cell_type": "code",
   "execution_count": 23,
   "id": "7853eef5",
   "metadata": {},
   "outputs": [],
   "source": [
    "import torch as th"
   ]
  },
  {
   "cell_type": "code",
   "execution_count": 24,
   "id": "ea1945dc",
   "metadata": {},
   "outputs": [],
   "source": [
    "import numpy as np"
   ]
  },
  {
   "cell_type": "code",
   "execution_count": 26,
   "id": "e97da144",
   "metadata": {},
   "outputs": [],
   "source": [
    "X = th.LongTensor(np.array(X))\n",
    "y = th.LongTensor(np.array(y))"
   ]
  },
  {
   "cell_type": "code",
   "execution_count": 47,
   "id": "4198be6b",
   "metadata": {},
   "outputs": [],
   "source": [
    "X = X.tag(\"The MNIST data set with 1797 images of 8*8 pixels\")"
   ]
  },
  {
   "cell_type": "code",
   "execution_count": 55,
   "id": "1de7d6b3",
   "metadata": {},
   "outputs": [
    {
     "data": {
      "text/plain": [
       "tensor([[ 0,  0,  5,  ...,  0,  0,  0],\n",
       "        [ 0,  0,  0,  ..., 10,  0,  0],\n",
       "        [ 0,  0,  0,  ..., 16,  9,  0],\n",
       "        ...,\n",
       "        [ 0,  0,  1,  ...,  6,  0,  0],\n",
       "        [ 0,  0,  2,  ..., 12,  0,  0],\n",
       "        [ 0,  0, 10,  ..., 12,  1,  0]])"
      ]
     },
     "execution_count": 55,
     "metadata": {},
     "output_type": "execute_result"
    },
    {
     "name": "stderr",
     "output_type": "stream",
     "text": [
      "[2021-08-09T18:41:14.699416+0100][CRITICAL][logger]][18048] <class 'syft.core.store.store_memory.MemoryStore'> __delitem__ error <UID: 29a7d19714bd4f1cb5c9f27b167995e2>.\n",
      "[2021-08-09T18:41:14.709059+0100][CRITICAL][logger]][18048] <class 'syft.core.store.store_memory.MemoryStore'> __delitem__ error <UID: 7213d96303a84b3eb28d46e541ca98e4>.\n",
      "[2021-08-09T18:41:14.718853+0100][CRITICAL][logger]][18048] <class 'syft.core.store.store_memory.MemoryStore'> __delitem__ error <UID: c49bbfc8f2d24c6889951979fed008b6>.\n",
      "[2021-08-09T18:41:14.727374+0100][CRITICAL][logger]][18048] <class 'syft.core.store.store_memory.MemoryStore'> __delitem__ error <UID: ff98d00d75fa488fa40664857063d39c>.\n",
      "[2021-08-09T18:41:14.735411+0100][CRITICAL][logger]][18048] <class 'syft.core.store.store_memory.MemoryStore'> __delitem__ error <UID: 3bd28b3fdd484161ae3eb003d17c6d6d>.\n",
      "[2021-08-09T18:41:14.743410+0100][CRITICAL][logger]][18048] <class 'syft.core.store.store_memory.MemoryStore'> __delitem__ error <UID: b5be0371672e48a7bc8bdd94664910d9>.\n",
      "[2021-08-09T18:41:14.752130+0100][CRITICAL][logger]][18048] <class 'syft.core.store.store_memory.MemoryStore'> __delitem__ error <UID: 562657661a6e49699cffe99fade5b675>.\n",
      "[2021-08-09T18:41:14.837825+0100][CRITICAL][logger]][18048] <class 'syft.core.store.store_memory.MemoryStore'> __delitem__ error <UID: 9918b6199dc74e4e9dc6e11813ebe37c>.\n",
      "[2021-08-09T18:41:14.842340+0100][CRITICAL][logger]][18048] <class 'syft.core.store.store_memory.MemoryStore'> __delitem__ error <UID: 0313d185cbac4ca6ac8d51cf39413e3b>.\n",
      "[2021-08-09T18:41:14.847475+0100][CRITICAL][logger]][18048] <class 'syft.core.store.store_memory.MemoryStore'> __delitem__ error <UID: 162d0e7b13144d759240f3dfc45778d3>.\n",
      "[2021-08-09T18:41:14.852554+0100][CRITICAL][logger]][18048] <class 'syft.core.store.store_memory.MemoryStore'> __delitem__ error <UID: ef6af58fb37044eeb9819eaa40e425d8>.\n",
      "[2021-08-09T18:41:14.857931+0100][CRITICAL][logger]][18048] <class 'syft.core.store.store_memory.MemoryStore'> __delitem__ error <UID: e7e8cc491506429b86c4ff5d4f5376ca>.\n",
      "[2021-08-09T18:41:14.862812+0100][CRITICAL][logger]][18048] <class 'syft.core.store.store_memory.MemoryStore'> __delitem__ error <UID: f0371722d7964bc29f6ad4e26a6dc31a>.\n",
      "[2021-08-09T18:41:14.865919+0100][CRITICAL][logger]][18048] <class 'syft.core.store.store_memory.MemoryStore'> __delitem__ error <UID: d986233133e846a7935e137cff1fa6d4>.\n",
      "[2021-08-09T18:41:14.871428+0100][CRITICAL][logger]][18048] <class 'syft.core.store.store_memory.MemoryStore'> __delitem__ error <UID: 2123af8ce12946aeb0407cae108714ab>.\n",
      "[2021-08-09T18:41:14.875428+0100][CRITICAL][logger]][18048] <class 'syft.core.store.store_memory.MemoryStore'> __delitem__ error <UID: 0d6f79c5e5cf41cd882f761f2ebcfc41>.\n"
     ]
    }
   ],
   "source": [
    "X"
   ]
  },
  {
   "cell_type": "code",
   "execution_count": 38,
   "id": "e03b6366",
   "metadata": {},
   "outputs": [],
   "source": [
    "data_pointer = X.send(duet,searchable=True)"
   ]
  },
  {
   "cell_type": "code",
   "execution_count": 39,
   "id": "4ccfc748",
   "metadata": {},
   "outputs": [
    {
     "name": "stdout",
     "output_type": "stream",
     "text": [
      "`searchable` is deprecated please use `pointable` in future\n"
     ]
    }
   ],
   "source": [
    "target_pointer = y.send(duet,searchable=True)"
   ]
  },
  {
   "cell_type": "code",
   "execution_count": 54,
   "id": "ec687484",
   "metadata": {},
   "outputs": [
    {
     "name": "stderr",
     "output_type": "stream",
     "text": [
      "[2021-08-09T18:39:42.818577+0100][CRITICAL][logger]][18048] <class 'syft.core.store.store_memory.MemoryStore'> __getitem__ error <UID: 9086c8694d384ecf837931ae00d56bf5> <UID: 9086c8694d384ecf837931ae00d56bf5>\n",
      "[2021-08-09T18:39:42.819580+0100][CRITICAL][logger]][18048] <UID: 9086c8694d384ecf837931ae00d56bf5>\n",
      "[2021-08-09T18:39:42.821580+0100][CRITICAL][logger]][18048] <UID: 9086c8694d384ecf837931ae00d56bf5>\n",
      "[2021-08-09T18:39:42.822577+0100][CRITICAL][logger]][18048] <UID: 9086c8694d384ecf837931ae00d56bf5>\n",
      "Exception in callback AsyncIOEventEmitter._emit_run.<locals>._callback(<Task finishe...1ae00d56bf5>)>) at C:\\Users\\21355\\Anaconda3\\envs\\pysyft\\lib\\site-packages\\pyee\\_asyncio.py:55\n",
      "handle: <Handle AsyncIOEventEmitter._emit_run.<locals>._callback(<Task finishe...1ae00d56bf5>)>) at C:\\Users\\21355\\Anaconda3\\envs\\pysyft\\lib\\site-packages\\pyee\\_asyncio.py:55>\n",
      "Traceback (most recent call last):\n",
      "  File \"C:\\Users\\21355\\Anaconda3\\envs\\pysyft\\lib\\asyncio\\events.py\", line 80, in _run\n",
      "    self._context.run(self._callback, *self._args)\n",
      "  File \"C:\\Users\\21355\\Anaconda3\\envs\\pysyft\\lib\\site-packages\\pyee\\_asyncio.py\", line 62, in _callback\n",
      "    self.emit('error', exc)\n",
      "  File \"C:\\Users\\21355\\Anaconda3\\envs\\pysyft\\lib\\site-packages\\pyee\\_base.py\", line 116, in emit\n",
      "    self._emit_handle_potential_error(event, args[0] if args else None)\n",
      "  File \"C:\\Users\\21355\\Anaconda3\\envs\\pysyft\\lib\\site-packages\\pyee\\_base.py\", line 86, in _emit_handle_potential_error\n",
      "    raise error\n",
      "  File \"C:\\Users\\21355\\Anaconda3\\envs\\pysyft\\lib\\asyncio\\tasks.py\", line 256, in __step\n",
      "    result = coro.send(None)\n",
      "  File \"C:\\Users\\21355\\Anaconda3\\envs\\pysyft\\lib\\site-packages\\syft\\grid\\connections\\webrtc.py\", line 233, in on_message\n",
      "    await self.consumer(msg=message)\n",
      "  File \"C:\\Users\\21355\\Anaconda3\\envs\\pysyft\\lib\\site-packages\\syft\\grid\\connections\\webrtc.py\", line 449, in consumer\n",
      "    traceback_and_raise(e)\n",
      "  File \"C:\\Users\\21355\\Anaconda3\\envs\\pysyft\\lib\\site-packages\\syft\\logger.py\", line 61, in traceback_and_raise\n",
      "    raise e\n",
      "  File \"C:\\Users\\21355\\Anaconda3\\envs\\pysyft\\lib\\site-packages\\syft\\grid\\connections\\webrtc.py\", line 434, in consumer\n",
      "    self.recv_immediate_msg_without_reply(msg=_msg)\n",
      "  File \"C:\\Users\\21355\\Anaconda3\\envs\\pysyft\\lib\\site-packages\\syft\\grid\\connections\\webrtc.py\", line 490, in recv_immediate_msg_without_reply\n",
      "    traceback_and_raise(e)\n",
      "  File \"C:\\Users\\21355\\Anaconda3\\envs\\pysyft\\lib\\site-packages\\syft\\logger.py\", line 61, in traceback_and_raise\n",
      "    raise e\n",
      "  File \"C:\\Users\\21355\\Anaconda3\\envs\\pysyft\\lib\\site-packages\\syft\\grid\\connections\\webrtc.py\", line 485, in recv_immediate_msg_without_reply\n",
      "    self.node.recv_immediate_msg_without_reply(msg=msg)\n",
      "  File \"C:\\Users\\21355\\Anaconda3\\envs\\pysyft\\lib\\site-packages\\syft\\core\\node\\common\\node.py\", line 399, in recv_immediate_msg_without_reply\n",
      "    self.process_message(msg=msg, router=self.immediate_msg_without_reply_router)\n",
      "  File \"C:\\Users\\21355\\Anaconda3\\envs\\pysyft\\lib\\site-packages\\syft\\core\\node\\common\\node.py\", line 481, in process_message\n",
      "    result = service.process(\n",
      "  File \"C:\\Users\\21355\\Anaconda3\\envs\\pysyft\\lib\\site-packages\\syft\\core\\node\\common\\service\\obj_action_service.py\", line 27, in process\n",
      "    msg.execute_action(node=node, verify_key=verify_key)\n",
      "  File \"C:\\Users\\21355\\Anaconda3\\envs\\pysyft\\lib\\site-packages\\syft\\core\\node\\common\\action\\run_class_method_action.py\", line 126, in execute_action\n",
      "    r_arg = node.store[arg.id_at_location]\n",
      "  File \"C:\\Users\\21355\\Anaconda3\\envs\\pysyft\\lib\\site-packages\\syft\\core\\store\\store_memory.py\", line 66, in __getitem__\n",
      "    traceback_and_raise(e)\n",
      "  File \"C:\\Users\\21355\\Anaconda3\\envs\\pysyft\\lib\\site-packages\\syft\\logger.py\", line 61, in traceback_and_raise\n",
      "    raise e\n",
      "  File \"C:\\Users\\21355\\Anaconda3\\envs\\pysyft\\lib\\site-packages\\syft\\core\\store\\store_memory.py\", line 63, in __getitem__\n",
      "    return self._objects[key]\n",
      "KeyError: <UID: 9086c8694d384ecf837931ae00d56bf5>\n",
      "[2021-08-09T18:39:42.832953+0100][CRITICAL][logger]][18048] <class 'syft.core.store.store_memory.MemoryStore'> __getitem__ error <UID: 5b7acb3f9a8844d9ac6db0c15e32066f> <UID: 5b7acb3f9a8844d9ac6db0c15e32066f>\n",
      "[2021-08-09T18:39:42.833935+0100][CRITICAL][logger]][18048] <UID: 5b7acb3f9a8844d9ac6db0c15e32066f>\n",
      "[2021-08-09T18:39:42.834926+0100][CRITICAL][logger]][18048] <UID: 5b7acb3f9a8844d9ac6db0c15e32066f>\n",
      "[2021-08-09T18:39:42.834926+0100][CRITICAL][logger]][18048] <UID: 5b7acb3f9a8844d9ac6db0c15e32066f>\n",
      "Exception in callback AsyncIOEventEmitter._emit_run.<locals>._callback(<Task finishe...0c15e32066f>)>) at C:\\Users\\21355\\Anaconda3\\envs\\pysyft\\lib\\site-packages\\pyee\\_asyncio.py:55\n",
      "handle: <Handle AsyncIOEventEmitter._emit_run.<locals>._callback(<Task finishe...0c15e32066f>)>) at C:\\Users\\21355\\Anaconda3\\envs\\pysyft\\lib\\site-packages\\pyee\\_asyncio.py:55>\n",
      "Traceback (most recent call last):\n",
      "  File \"C:\\Users\\21355\\Anaconda3\\envs\\pysyft\\lib\\asyncio\\events.py\", line 80, in _run\n",
      "    self._context.run(self._callback, *self._args)\n",
      "  File \"C:\\Users\\21355\\Anaconda3\\envs\\pysyft\\lib\\site-packages\\pyee\\_asyncio.py\", line 62, in _callback\n",
      "    self.emit('error', exc)\n",
      "  File \"C:\\Users\\21355\\Anaconda3\\envs\\pysyft\\lib\\site-packages\\pyee\\_base.py\", line 116, in emit\n",
      "    self._emit_handle_potential_error(event, args[0] if args else None)\n",
      "  File \"C:\\Users\\21355\\Anaconda3\\envs\\pysyft\\lib\\site-packages\\pyee\\_base.py\", line 86, in _emit_handle_potential_error\n",
      "    raise error\n",
      "  File \"C:\\Users\\21355\\Anaconda3\\envs\\pysyft\\lib\\asyncio\\tasks.py\", line 256, in __step\n",
      "    result = coro.send(None)\n",
      "  File \"C:\\Users\\21355\\Anaconda3\\envs\\pysyft\\lib\\site-packages\\syft\\grid\\connections\\webrtc.py\", line 233, in on_message\n",
      "    await self.consumer(msg=message)\n",
      "  File \"C:\\Users\\21355\\Anaconda3\\envs\\pysyft\\lib\\site-packages\\syft\\grid\\connections\\webrtc.py\", line 449, in consumer\n",
      "    traceback_and_raise(e)\n",
      "  File \"C:\\Users\\21355\\Anaconda3\\envs\\pysyft\\lib\\site-packages\\syft\\logger.py\", line 61, in traceback_and_raise\n",
      "    raise e\n",
      "  File \"C:\\Users\\21355\\Anaconda3\\envs\\pysyft\\lib\\site-packages\\syft\\grid\\connections\\webrtc.py\", line 434, in consumer\n",
      "    self.recv_immediate_msg_without_reply(msg=_msg)\n",
      "  File \"C:\\Users\\21355\\Anaconda3\\envs\\pysyft\\lib\\site-packages\\syft\\grid\\connections\\webrtc.py\", line 490, in recv_immediate_msg_without_reply\n",
      "    traceback_and_raise(e)\n",
      "  File \"C:\\Users\\21355\\Anaconda3\\envs\\pysyft\\lib\\site-packages\\syft\\logger.py\", line 61, in traceback_and_raise\n",
      "    raise e\n",
      "  File \"C:\\Users\\21355\\Anaconda3\\envs\\pysyft\\lib\\site-packages\\syft\\grid\\connections\\webrtc.py\", line 485, in recv_immediate_msg_without_reply\n",
      "    self.node.recv_immediate_msg_without_reply(msg=msg)\n",
      "  File \"C:\\Users\\21355\\Anaconda3\\envs\\pysyft\\lib\\site-packages\\syft\\core\\node\\common\\node.py\", line 399, in recv_immediate_msg_without_reply\n",
      "    self.process_message(msg=msg, router=self.immediate_msg_without_reply_router)\n",
      "  File \"C:\\Users\\21355\\Anaconda3\\envs\\pysyft\\lib\\site-packages\\syft\\core\\node\\common\\node.py\", line 481, in process_message\n",
      "    result = service.process(\n",
      "  File \"C:\\Users\\21355\\Anaconda3\\envs\\pysyft\\lib\\site-packages\\syft\\core\\node\\common\\service\\obj_action_service.py\", line 27, in process\n",
      "    msg.execute_action(node=node, verify_key=verify_key)\n",
      "  File \"C:\\Users\\21355\\Anaconda3\\envs\\pysyft\\lib\\site-packages\\syft\\core\\node\\common\\action\\function_or_constructor_action.py\", line 94, in execute_action\n",
      "    r_arg = node.store[arg.id_at_location]\n",
      "  File \"C:\\Users\\21355\\Anaconda3\\envs\\pysyft\\lib\\site-packages\\syft\\core\\store\\store_memory.py\", line 66, in __getitem__\n",
      "    traceback_and_raise(e)\n",
      "  File \"C:\\Users\\21355\\Anaconda3\\envs\\pysyft\\lib\\site-packages\\syft\\logger.py\", line 61, in traceback_and_raise\n",
      "    raise e\n",
      "  File \"C:\\Users\\21355\\Anaconda3\\envs\\pysyft\\lib\\site-packages\\syft\\core\\store\\store_memory.py\", line 63, in __getitem__\n",
      "    return self._objects[key]\n",
      "KeyError: <UID: 5b7acb3f9a8844d9ac6db0c15e32066f>\n",
      "[2021-08-09T18:39:42.943858+0100][CRITICAL][logger]][18048] <class 'syft.core.store.store_memory.MemoryStore'> __delitem__ error <UID: 5b7acb3f9a8844d9ac6db0c15e32066f>.\n",
      "[2021-08-09T18:39:42.954302+0100][CRITICAL][logger]][18048] <class 'syft.core.store.store_memory.MemoryStore'> __getitem__ error <UID: bc827e97d44b466d9992614cad417ea6> <UID: bc827e97d44b466d9992614cad417ea6>\n"
     ]
    },
    {
     "name": "stderr",
     "output_type": "stream",
     "text": [
      "[2021-08-09T18:39:42.955748+0100][CRITICAL][logger]][18048] <UID: bc827e97d44b466d9992614cad417ea6>\n",
      "[2021-08-09T18:39:42.956719+0100][CRITICAL][logger]][18048] <UID: bc827e97d44b466d9992614cad417ea6>\n",
      "[2021-08-09T18:39:42.957719+0100][CRITICAL][logger]][18048] <UID: bc827e97d44b466d9992614cad417ea6>\n",
      "Exception in callback AsyncIOEventEmitter._emit_run.<locals>._callback(<Task finishe...14cad417ea6>)>) at C:\\Users\\21355\\Anaconda3\\envs\\pysyft\\lib\\site-packages\\pyee\\_asyncio.py:55\n",
      "handle: <Handle AsyncIOEventEmitter._emit_run.<locals>._callback(<Task finishe...14cad417ea6>)>) at C:\\Users\\21355\\Anaconda3\\envs\\pysyft\\lib\\site-packages\\pyee\\_asyncio.py:55>\n",
      "Traceback (most recent call last):\n",
      "  File \"C:\\Users\\21355\\Anaconda3\\envs\\pysyft\\lib\\asyncio\\events.py\", line 80, in _run\n",
      "    self._context.run(self._callback, *self._args)\n",
      "  File \"C:\\Users\\21355\\Anaconda3\\envs\\pysyft\\lib\\site-packages\\pyee\\_asyncio.py\", line 62, in _callback\n",
      "    self.emit('error', exc)\n",
      "  File \"C:\\Users\\21355\\Anaconda3\\envs\\pysyft\\lib\\site-packages\\pyee\\_base.py\", line 116, in emit\n",
      "    self._emit_handle_potential_error(event, args[0] if args else None)\n",
      "  File \"C:\\Users\\21355\\Anaconda3\\envs\\pysyft\\lib\\site-packages\\pyee\\_base.py\", line 86, in _emit_handle_potential_error\n",
      "    raise error\n",
      "  File \"C:\\Users\\21355\\Anaconda3\\envs\\pysyft\\lib\\asyncio\\tasks.py\", line 256, in __step\n",
      "    result = coro.send(None)\n",
      "  File \"C:\\Users\\21355\\Anaconda3\\envs\\pysyft\\lib\\site-packages\\syft\\grid\\connections\\webrtc.py\", line 233, in on_message\n",
      "    await self.consumer(msg=message)\n",
      "  File \"C:\\Users\\21355\\Anaconda3\\envs\\pysyft\\lib\\site-packages\\syft\\grid\\connections\\webrtc.py\", line 449, in consumer\n",
      "    traceback_and_raise(e)\n",
      "  File \"C:\\Users\\21355\\Anaconda3\\envs\\pysyft\\lib\\site-packages\\syft\\logger.py\", line 61, in traceback_and_raise\n",
      "    raise e\n",
      "  File \"C:\\Users\\21355\\Anaconda3\\envs\\pysyft\\lib\\site-packages\\syft\\grid\\connections\\webrtc.py\", line 434, in consumer\n",
      "    self.recv_immediate_msg_without_reply(msg=_msg)\n",
      "  File \"C:\\Users\\21355\\Anaconda3\\envs\\pysyft\\lib\\site-packages\\syft\\grid\\connections\\webrtc.py\", line 490, in recv_immediate_msg_without_reply\n",
      "    traceback_and_raise(e)\n",
      "  File \"C:\\Users\\21355\\Anaconda3\\envs\\pysyft\\lib\\site-packages\\syft\\logger.py\", line 61, in traceback_and_raise\n",
      "    raise e\n",
      "  File \"C:\\Users\\21355\\Anaconda3\\envs\\pysyft\\lib\\site-packages\\syft\\grid\\connections\\webrtc.py\", line 485, in recv_immediate_msg_without_reply\n",
      "    self.node.recv_immediate_msg_without_reply(msg=msg)\n",
      "  File \"C:\\Users\\21355\\Anaconda3\\envs\\pysyft\\lib\\site-packages\\syft\\core\\node\\common\\node.py\", line 399, in recv_immediate_msg_without_reply\n",
      "    self.process_message(msg=msg, router=self.immediate_msg_without_reply_router)\n",
      "  File \"C:\\Users\\21355\\Anaconda3\\envs\\pysyft\\lib\\site-packages\\syft\\core\\node\\common\\node.py\", line 481, in process_message\n",
      "    result = service.process(\n",
      "  File \"C:\\Users\\21355\\Anaconda3\\envs\\pysyft\\lib\\site-packages\\syft\\core\\node\\common\\service\\obj_action_service.py\", line 27, in process\n",
      "    msg.execute_action(node=node, verify_key=verify_key)\n",
      "  File \"C:\\Users\\21355\\Anaconda3\\envs\\pysyft\\lib\\site-packages\\syft\\core\\node\\common\\action\\run_class_method_action.py\", line 126, in execute_action\n",
      "    r_arg = node.store[arg.id_at_location]\n",
      "  File \"C:\\Users\\21355\\Anaconda3\\envs\\pysyft\\lib\\site-packages\\syft\\core\\store\\store_memory.py\", line 66, in __getitem__\n",
      "    traceback_and_raise(e)\n",
      "  File \"C:\\Users\\21355\\Anaconda3\\envs\\pysyft\\lib\\site-packages\\syft\\logger.py\", line 61, in traceback_and_raise\n",
      "    raise e\n",
      "  File \"C:\\Users\\21355\\Anaconda3\\envs\\pysyft\\lib\\site-packages\\syft\\core\\store\\store_memory.py\", line 63, in __getitem__\n",
      "    return self._objects[key]\n",
      "KeyError: <UID: bc827e97d44b466d9992614cad417ea6>\n",
      "[2021-08-09T18:39:42.968708+0100][CRITICAL][logger]][18048] <class 'syft.core.store.store_memory.MemoryStore'> __getitem__ error <UID: a2d2addd606d4da5ac1110aef7cb13f7> <UID: a2d2addd606d4da5ac1110aef7cb13f7>\n",
      "[2021-08-09T18:39:42.971484+0100][CRITICAL][logger]][18048] <UID: a2d2addd606d4da5ac1110aef7cb13f7>\n",
      "[2021-08-09T18:39:42.971484+0100][CRITICAL][logger]][18048] <UID: a2d2addd606d4da5ac1110aef7cb13f7>\n",
      "[2021-08-09T18:39:42.971484+0100][CRITICAL][logger]][18048] <UID: a2d2addd606d4da5ac1110aef7cb13f7>\n",
      "Exception in callback AsyncIOEventEmitter._emit_run.<locals>._callback(<Task finishe...0aef7cb13f7>)>) at C:\\Users\\21355\\Anaconda3\\envs\\pysyft\\lib\\site-packages\\pyee\\_asyncio.py:55\n",
      "handle: <Handle AsyncIOEventEmitter._emit_run.<locals>._callback(<Task finishe...0aef7cb13f7>)>) at C:\\Users\\21355\\Anaconda3\\envs\\pysyft\\lib\\site-packages\\pyee\\_asyncio.py:55>\n",
      "Traceback (most recent call last):\n",
      "  File \"C:\\Users\\21355\\Anaconda3\\envs\\pysyft\\lib\\asyncio\\events.py\", line 80, in _run\n",
      "    self._context.run(self._callback, *self._args)\n",
      "  File \"C:\\Users\\21355\\Anaconda3\\envs\\pysyft\\lib\\site-packages\\pyee\\_asyncio.py\", line 62, in _callback\n",
      "    self.emit('error', exc)\n",
      "  File \"C:\\Users\\21355\\Anaconda3\\envs\\pysyft\\lib\\site-packages\\pyee\\_base.py\", line 116, in emit\n",
      "    self._emit_handle_potential_error(event, args[0] if args else None)\n",
      "  File \"C:\\Users\\21355\\Anaconda3\\envs\\pysyft\\lib\\site-packages\\pyee\\_base.py\", line 86, in _emit_handle_potential_error\n",
      "    raise error\n",
      "  File \"C:\\Users\\21355\\Anaconda3\\envs\\pysyft\\lib\\asyncio\\tasks.py\", line 256, in __step\n",
      "    result = coro.send(None)\n",
      "  File \"C:\\Users\\21355\\Anaconda3\\envs\\pysyft\\lib\\site-packages\\syft\\grid\\connections\\webrtc.py\", line 233, in on_message\n",
      "    await self.consumer(msg=message)\n",
      "  File \"C:\\Users\\21355\\Anaconda3\\envs\\pysyft\\lib\\site-packages\\syft\\grid\\connections\\webrtc.py\", line 449, in consumer\n",
      "    traceback_and_raise(e)\n",
      "  File \"C:\\Users\\21355\\Anaconda3\\envs\\pysyft\\lib\\site-packages\\syft\\logger.py\", line 61, in traceback_and_raise\n",
      "    raise e\n",
      "  File \"C:\\Users\\21355\\Anaconda3\\envs\\pysyft\\lib\\site-packages\\syft\\grid\\connections\\webrtc.py\", line 434, in consumer\n",
      "    self.recv_immediate_msg_without_reply(msg=_msg)\n",
      "  File \"C:\\Users\\21355\\Anaconda3\\envs\\pysyft\\lib\\site-packages\\syft\\grid\\connections\\webrtc.py\", line 490, in recv_immediate_msg_without_reply\n",
      "    traceback_and_raise(e)\n",
      "  File \"C:\\Users\\21355\\Anaconda3\\envs\\pysyft\\lib\\site-packages\\syft\\logger.py\", line 61, in traceback_and_raise\n",
      "    raise e\n",
      "  File \"C:\\Users\\21355\\Anaconda3\\envs\\pysyft\\lib\\site-packages\\syft\\grid\\connections\\webrtc.py\", line 485, in recv_immediate_msg_without_reply\n",
      "    self.node.recv_immediate_msg_without_reply(msg=msg)\n",
      "  File \"C:\\Users\\21355\\Anaconda3\\envs\\pysyft\\lib\\site-packages\\syft\\core\\node\\common\\node.py\", line 399, in recv_immediate_msg_without_reply\n",
      "    self.process_message(msg=msg, router=self.immediate_msg_without_reply_router)\n",
      "  File \"C:\\Users\\21355\\Anaconda3\\envs\\pysyft\\lib\\site-packages\\syft\\core\\node\\common\\node.py\", line 481, in process_message\n",
      "    result = service.process(\n",
      "  File \"C:\\Users\\21355\\Anaconda3\\envs\\pysyft\\lib\\site-packages\\syft\\core\\node\\common\\service\\obj_action_service.py\", line 27, in process\n",
      "    msg.execute_action(node=node, verify_key=verify_key)\n",
      "  File \"C:\\Users\\21355\\Anaconda3\\envs\\pysyft\\lib\\site-packages\\syft\\core\\node\\common\\action\\function_or_constructor_action.py\", line 94, in execute_action\n",
      "    r_arg = node.store[arg.id_at_location]\n",
      "  File \"C:\\Users\\21355\\Anaconda3\\envs\\pysyft\\lib\\site-packages\\syft\\core\\store\\store_memory.py\", line 66, in __getitem__\n",
      "    traceback_and_raise(e)\n",
      "  File \"C:\\Users\\21355\\Anaconda3\\envs\\pysyft\\lib\\site-packages\\syft\\logger.py\", line 61, in traceback_and_raise\n",
      "    raise e\n",
      "  File \"C:\\Users\\21355\\Anaconda3\\envs\\pysyft\\lib\\site-packages\\syft\\core\\store\\store_memory.py\", line 63, in __getitem__\n",
      "    return self._objects[key]\n",
      "KeyError: <UID: a2d2addd606d4da5ac1110aef7cb13f7>\n",
      "[2021-08-09T18:39:42.984922+0100][CRITICAL][logger]][18048] <class 'syft.core.store.store_memory.MemoryStore'> __delitem__ error <UID: a2d2addd606d4da5ac1110aef7cb13f7>.\n",
      "[2021-08-09T18:39:42.990601+0100][CRITICAL][logger]][18048] <class 'syft.core.store.store_memory.MemoryStore'> __delitem__ error <UID: bc827e97d44b466d9992614cad417ea6>.\n",
      "[2021-08-09T18:39:42.998380+0100][CRITICAL][logger]][18048] <class 'syft.core.store.store_memory.MemoryStore'> __getitem__ error <UID: b439367fa1e34a9dae63157e82af9f15> <UID: b439367fa1e34a9dae63157e82af9f15>\n",
      "[2021-08-09T18:39:42.999181+0100][CRITICAL][logger]][18048] <UID: b439367fa1e34a9dae63157e82af9f15>\n"
     ]
    },
    {
     "name": "stderr",
     "output_type": "stream",
     "text": [
      "[2021-08-09T18:39:42.999908+0100][CRITICAL][logger]][18048] <UID: b439367fa1e34a9dae63157e82af9f15>\n",
      "[2021-08-09T18:39:43.003883+0100][CRITICAL][logger]][18048] <UID: b439367fa1e34a9dae63157e82af9f15>\n",
      "Exception in callback AsyncIOEventEmitter._emit_run.<locals>._callback(<Task finishe...57e82af9f15>)>) at C:\\Users\\21355\\Anaconda3\\envs\\pysyft\\lib\\site-packages\\pyee\\_asyncio.py:55\n",
      "handle: <Handle AsyncIOEventEmitter._emit_run.<locals>._callback(<Task finishe...57e82af9f15>)>) at C:\\Users\\21355\\Anaconda3\\envs\\pysyft\\lib\\site-packages\\pyee\\_asyncio.py:55>\n",
      "Traceback (most recent call last):\n",
      "  File \"C:\\Users\\21355\\Anaconda3\\envs\\pysyft\\lib\\asyncio\\events.py\", line 80, in _run\n",
      "    self._context.run(self._callback, *self._args)\n",
      "  File \"C:\\Users\\21355\\Anaconda3\\envs\\pysyft\\lib\\site-packages\\pyee\\_asyncio.py\", line 62, in _callback\n",
      "    self.emit('error', exc)\n",
      "  File \"C:\\Users\\21355\\Anaconda3\\envs\\pysyft\\lib\\site-packages\\pyee\\_base.py\", line 116, in emit\n",
      "    self._emit_handle_potential_error(event, args[0] if args else None)\n",
      "  File \"C:\\Users\\21355\\Anaconda3\\envs\\pysyft\\lib\\site-packages\\pyee\\_base.py\", line 86, in _emit_handle_potential_error\n",
      "    raise error\n",
      "  File \"C:\\Users\\21355\\Anaconda3\\envs\\pysyft\\lib\\asyncio\\tasks.py\", line 256, in __step\n",
      "    result = coro.send(None)\n",
      "  File \"C:\\Users\\21355\\Anaconda3\\envs\\pysyft\\lib\\site-packages\\syft\\grid\\connections\\webrtc.py\", line 233, in on_message\n",
      "    await self.consumer(msg=message)\n",
      "  File \"C:\\Users\\21355\\Anaconda3\\envs\\pysyft\\lib\\site-packages\\syft\\grid\\connections\\webrtc.py\", line 449, in consumer\n",
      "    traceback_and_raise(e)\n",
      "  File \"C:\\Users\\21355\\Anaconda3\\envs\\pysyft\\lib\\site-packages\\syft\\logger.py\", line 61, in traceback_and_raise\n",
      "    raise e\n",
      "  File \"C:\\Users\\21355\\Anaconda3\\envs\\pysyft\\lib\\site-packages\\syft\\grid\\connections\\webrtc.py\", line 434, in consumer\n",
      "    self.recv_immediate_msg_without_reply(msg=_msg)\n",
      "  File \"C:\\Users\\21355\\Anaconda3\\envs\\pysyft\\lib\\site-packages\\syft\\grid\\connections\\webrtc.py\", line 490, in recv_immediate_msg_without_reply\n",
      "    traceback_and_raise(e)\n",
      "  File \"C:\\Users\\21355\\Anaconda3\\envs\\pysyft\\lib\\site-packages\\syft\\logger.py\", line 61, in traceback_and_raise\n",
      "    raise e\n",
      "  File \"C:\\Users\\21355\\Anaconda3\\envs\\pysyft\\lib\\site-packages\\syft\\grid\\connections\\webrtc.py\", line 485, in recv_immediate_msg_without_reply\n",
      "    self.node.recv_immediate_msg_without_reply(msg=msg)\n",
      "  File \"C:\\Users\\21355\\Anaconda3\\envs\\pysyft\\lib\\site-packages\\syft\\core\\node\\common\\node.py\", line 399, in recv_immediate_msg_without_reply\n",
      "    self.process_message(msg=msg, router=self.immediate_msg_without_reply_router)\n",
      "  File \"C:\\Users\\21355\\Anaconda3\\envs\\pysyft\\lib\\site-packages\\syft\\core\\node\\common\\node.py\", line 481, in process_message\n",
      "    result = service.process(\n",
      "  File \"C:\\Users\\21355\\Anaconda3\\envs\\pysyft\\lib\\site-packages\\syft\\core\\node\\common\\service\\obj_action_service.py\", line 27, in process\n",
      "    msg.execute_action(node=node, verify_key=verify_key)\n",
      "  File \"C:\\Users\\21355\\Anaconda3\\envs\\pysyft\\lib\\site-packages\\syft\\core\\node\\common\\action\\run_class_method_action.py\", line 126, in execute_action\n",
      "    r_arg = node.store[arg.id_at_location]\n",
      "  File \"C:\\Users\\21355\\Anaconda3\\envs\\pysyft\\lib\\site-packages\\syft\\core\\store\\store_memory.py\", line 66, in __getitem__\n",
      "    traceback_and_raise(e)\n",
      "  File \"C:\\Users\\21355\\Anaconda3\\envs\\pysyft\\lib\\site-packages\\syft\\logger.py\", line 61, in traceback_and_raise\n",
      "    raise e\n",
      "  File \"C:\\Users\\21355\\Anaconda3\\envs\\pysyft\\lib\\site-packages\\syft\\core\\store\\store_memory.py\", line 63, in __getitem__\n",
      "    return self._objects[key]\n",
      "KeyError: <UID: b439367fa1e34a9dae63157e82af9f15>\n",
      "[2021-08-09T18:39:43.012644+0100][CRITICAL][logger]][18048] <class 'syft.core.store.store_memory.MemoryStore'> __getitem__ error <UID: 6f2903c39018434f9463e733d55021fd> <UID: 6f2903c39018434f9463e733d55021fd>\n",
      "[2021-08-09T18:39:43.014630+0100][CRITICAL][logger]][18048] <UID: 6f2903c39018434f9463e733d55021fd>\n",
      "[2021-08-09T18:39:43.015621+0100][CRITICAL][logger]][18048] <UID: 6f2903c39018434f9463e733d55021fd>\n",
      "[2021-08-09T18:39:43.017209+0100][CRITICAL][logger]][18048] <UID: 6f2903c39018434f9463e733d55021fd>\n",
      "Exception in callback AsyncIOEventEmitter._emit_run.<locals>._callback(<Task finishe...733d55021fd>)>) at C:\\Users\\21355\\Anaconda3\\envs\\pysyft\\lib\\site-packages\\pyee\\_asyncio.py:55\n",
      "handle: <Handle AsyncIOEventEmitter._emit_run.<locals>._callback(<Task finishe...733d55021fd>)>) at C:\\Users\\21355\\Anaconda3\\envs\\pysyft\\lib\\site-packages\\pyee\\_asyncio.py:55>\n",
      "Traceback (most recent call last):\n",
      "  File \"C:\\Users\\21355\\Anaconda3\\envs\\pysyft\\lib\\asyncio\\events.py\", line 80, in _run\n",
      "    self._context.run(self._callback, *self._args)\n",
      "  File \"C:\\Users\\21355\\Anaconda3\\envs\\pysyft\\lib\\site-packages\\pyee\\_asyncio.py\", line 62, in _callback\n",
      "    self.emit('error', exc)\n",
      "  File \"C:\\Users\\21355\\Anaconda3\\envs\\pysyft\\lib\\site-packages\\pyee\\_base.py\", line 116, in emit\n",
      "    self._emit_handle_potential_error(event, args[0] if args else None)\n",
      "  File \"C:\\Users\\21355\\Anaconda3\\envs\\pysyft\\lib\\site-packages\\pyee\\_base.py\", line 86, in _emit_handle_potential_error\n",
      "    raise error\n",
      "  File \"C:\\Users\\21355\\Anaconda3\\envs\\pysyft\\lib\\asyncio\\tasks.py\", line 256, in __step\n",
      "    result = coro.send(None)\n",
      "  File \"C:\\Users\\21355\\Anaconda3\\envs\\pysyft\\lib\\site-packages\\syft\\grid\\connections\\webrtc.py\", line 233, in on_message\n",
      "    await self.consumer(msg=message)\n",
      "  File \"C:\\Users\\21355\\Anaconda3\\envs\\pysyft\\lib\\site-packages\\syft\\grid\\connections\\webrtc.py\", line 449, in consumer\n",
      "    traceback_and_raise(e)\n",
      "  File \"C:\\Users\\21355\\Anaconda3\\envs\\pysyft\\lib\\site-packages\\syft\\logger.py\", line 61, in traceback_and_raise\n",
      "    raise e\n",
      "  File \"C:\\Users\\21355\\Anaconda3\\envs\\pysyft\\lib\\site-packages\\syft\\grid\\connections\\webrtc.py\", line 434, in consumer\n",
      "    self.recv_immediate_msg_without_reply(msg=_msg)\n",
      "  File \"C:\\Users\\21355\\Anaconda3\\envs\\pysyft\\lib\\site-packages\\syft\\grid\\connections\\webrtc.py\", line 490, in recv_immediate_msg_without_reply\n",
      "    traceback_and_raise(e)\n",
      "  File \"C:\\Users\\21355\\Anaconda3\\envs\\pysyft\\lib\\site-packages\\syft\\logger.py\", line 61, in traceback_and_raise\n",
      "    raise e\n",
      "  File \"C:\\Users\\21355\\Anaconda3\\envs\\pysyft\\lib\\site-packages\\syft\\grid\\connections\\webrtc.py\", line 485, in recv_immediate_msg_without_reply\n",
      "    self.node.recv_immediate_msg_without_reply(msg=msg)\n",
      "  File \"C:\\Users\\21355\\Anaconda3\\envs\\pysyft\\lib\\site-packages\\syft\\core\\node\\common\\node.py\", line 399, in recv_immediate_msg_without_reply\n",
      "    self.process_message(msg=msg, router=self.immediate_msg_without_reply_router)\n",
      "  File \"C:\\Users\\21355\\Anaconda3\\envs\\pysyft\\lib\\site-packages\\syft\\core\\node\\common\\node.py\", line 481, in process_message\n",
      "    result = service.process(\n",
      "  File \"C:\\Users\\21355\\Anaconda3\\envs\\pysyft\\lib\\site-packages\\syft\\core\\node\\common\\service\\obj_action_service.py\", line 27, in process\n",
      "    msg.execute_action(node=node, verify_key=verify_key)\n",
      "  File \"C:\\Users\\21355\\Anaconda3\\envs\\pysyft\\lib\\site-packages\\syft\\core\\node\\common\\action\\function_or_constructor_action.py\", line 94, in execute_action\n",
      "    r_arg = node.store[arg.id_at_location]\n",
      "  File \"C:\\Users\\21355\\Anaconda3\\envs\\pysyft\\lib\\site-packages\\syft\\core\\store\\store_memory.py\", line 66, in __getitem__\n",
      "    traceback_and_raise(e)\n",
      "  File \"C:\\Users\\21355\\Anaconda3\\envs\\pysyft\\lib\\site-packages\\syft\\logger.py\", line 61, in traceback_and_raise\n",
      "    raise e\n",
      "  File \"C:\\Users\\21355\\Anaconda3\\envs\\pysyft\\lib\\site-packages\\syft\\core\\store\\store_memory.py\", line 63, in __getitem__\n",
      "    return self._objects[key]\n",
      "KeyError: <UID: 6f2903c39018434f9463e733d55021fd>\n",
      "[2021-08-09T18:39:43.032574+0100][CRITICAL][logger]][18048] <class 'syft.core.store.store_memory.MemoryStore'> __delitem__ error <UID: 6f2903c39018434f9463e733d55021fd>.\n",
      "[2021-08-09T18:39:43.037272+0100][CRITICAL][logger]][18048] <class 'syft.core.store.store_memory.MemoryStore'> __delitem__ error <UID: b439367fa1e34a9dae63157e82af9f15>.\n",
      "[2021-08-09T18:39:43.041143+0100][CRITICAL][logger]][18048] <class 'syft.core.store.store_memory.MemoryStore'> __getitem__ error <UID: aff212337ae94f38a7678fc7434de78c> <UID: aff212337ae94f38a7678fc7434de78c>\n",
      "[2021-08-09T18:39:43.041143+0100][CRITICAL][logger]][18048] <UID: aff212337ae94f38a7678fc7434de78c>\n",
      "[2021-08-09T18:39:43.041143+0100][CRITICAL][logger]][18048] <UID: aff212337ae94f38a7678fc7434de78c>\n"
     ]
    },
    {
     "name": "stderr",
     "output_type": "stream",
     "text": [
      "[2021-08-09T18:39:43.041143+0100][CRITICAL][logger]][18048] <UID: aff212337ae94f38a7678fc7434de78c>\n",
      "Exception in callback AsyncIOEventEmitter._emit_run.<locals>._callback(<Task finishe...fc7434de78c>)>) at C:\\Users\\21355\\Anaconda3\\envs\\pysyft\\lib\\site-packages\\pyee\\_asyncio.py:55\n",
      "handle: <Handle AsyncIOEventEmitter._emit_run.<locals>._callback(<Task finishe...fc7434de78c>)>) at C:\\Users\\21355\\Anaconda3\\envs\\pysyft\\lib\\site-packages\\pyee\\_asyncio.py:55>\n",
      "Traceback (most recent call last):\n",
      "  File \"C:\\Users\\21355\\Anaconda3\\envs\\pysyft\\lib\\asyncio\\events.py\", line 80, in _run\n",
      "    self._context.run(self._callback, *self._args)\n",
      "  File \"C:\\Users\\21355\\Anaconda3\\envs\\pysyft\\lib\\site-packages\\pyee\\_asyncio.py\", line 62, in _callback\n",
      "    self.emit('error', exc)\n",
      "  File \"C:\\Users\\21355\\Anaconda3\\envs\\pysyft\\lib\\site-packages\\pyee\\_base.py\", line 116, in emit\n",
      "    self._emit_handle_potential_error(event, args[0] if args else None)\n",
      "  File \"C:\\Users\\21355\\Anaconda3\\envs\\pysyft\\lib\\site-packages\\pyee\\_base.py\", line 86, in _emit_handle_potential_error\n",
      "    raise error\n",
      "  File \"C:\\Users\\21355\\Anaconda3\\envs\\pysyft\\lib\\asyncio\\tasks.py\", line 256, in __step\n",
      "    result = coro.send(None)\n",
      "  File \"C:\\Users\\21355\\Anaconda3\\envs\\pysyft\\lib\\site-packages\\syft\\grid\\connections\\webrtc.py\", line 233, in on_message\n",
      "    await self.consumer(msg=message)\n",
      "  File \"C:\\Users\\21355\\Anaconda3\\envs\\pysyft\\lib\\site-packages\\syft\\grid\\connections\\webrtc.py\", line 449, in consumer\n",
      "    traceback_and_raise(e)\n",
      "  File \"C:\\Users\\21355\\Anaconda3\\envs\\pysyft\\lib\\site-packages\\syft\\logger.py\", line 61, in traceback_and_raise\n",
      "    raise e\n",
      "  File \"C:\\Users\\21355\\Anaconda3\\envs\\pysyft\\lib\\site-packages\\syft\\grid\\connections\\webrtc.py\", line 434, in consumer\n",
      "    self.recv_immediate_msg_without_reply(msg=_msg)\n",
      "  File \"C:\\Users\\21355\\Anaconda3\\envs\\pysyft\\lib\\site-packages\\syft\\grid\\connections\\webrtc.py\", line 490, in recv_immediate_msg_without_reply\n",
      "    traceback_and_raise(e)\n",
      "  File \"C:\\Users\\21355\\Anaconda3\\envs\\pysyft\\lib\\site-packages\\syft\\logger.py\", line 61, in traceback_and_raise\n",
      "    raise e\n",
      "  File \"C:\\Users\\21355\\Anaconda3\\envs\\pysyft\\lib\\site-packages\\syft\\grid\\connections\\webrtc.py\", line 485, in recv_immediate_msg_without_reply\n",
      "    self.node.recv_immediate_msg_without_reply(msg=msg)\n",
      "  File \"C:\\Users\\21355\\Anaconda3\\envs\\pysyft\\lib\\site-packages\\syft\\core\\node\\common\\node.py\", line 399, in recv_immediate_msg_without_reply\n",
      "    self.process_message(msg=msg, router=self.immediate_msg_without_reply_router)\n",
      "  File \"C:\\Users\\21355\\Anaconda3\\envs\\pysyft\\lib\\site-packages\\syft\\core\\node\\common\\node.py\", line 481, in process_message\n",
      "    result = service.process(\n",
      "  File \"C:\\Users\\21355\\Anaconda3\\envs\\pysyft\\lib\\site-packages\\syft\\core\\node\\common\\service\\obj_action_service.py\", line 27, in process\n",
      "    msg.execute_action(node=node, verify_key=verify_key)\n",
      "  File \"C:\\Users\\21355\\Anaconda3\\envs\\pysyft\\lib\\site-packages\\syft\\core\\node\\common\\action\\run_class_method_action.py\", line 126, in execute_action\n",
      "    r_arg = node.store[arg.id_at_location]\n",
      "  File \"C:\\Users\\21355\\Anaconda3\\envs\\pysyft\\lib\\site-packages\\syft\\core\\store\\store_memory.py\", line 66, in __getitem__\n",
      "    traceback_and_raise(e)\n",
      "  File \"C:\\Users\\21355\\Anaconda3\\envs\\pysyft\\lib\\site-packages\\syft\\logger.py\", line 61, in traceback_and_raise\n",
      "    raise e\n",
      "  File \"C:\\Users\\21355\\Anaconda3\\envs\\pysyft\\lib\\site-packages\\syft\\core\\store\\store_memory.py\", line 63, in __getitem__\n",
      "    return self._objects[key]\n",
      "KeyError: <UID: aff212337ae94f38a7678fc7434de78c>\n",
      "[2021-08-09T18:39:43.065862+0100][CRITICAL][logger]][18048] <class 'syft.core.store.store_memory.MemoryStore'> __getitem__ error <UID: 59a261af8f3d40b9847c2b8f4262d8ba> <UID: 59a261af8f3d40b9847c2b8f4262d8ba>\n",
      "[2021-08-09T18:39:43.065862+0100][CRITICAL][logger]][18048] <UID: 59a261af8f3d40b9847c2b8f4262d8ba>\n",
      "[2021-08-09T18:39:43.065862+0100][CRITICAL][logger]][18048] <UID: 59a261af8f3d40b9847c2b8f4262d8ba>\n",
      "[2021-08-09T18:39:43.065862+0100][CRITICAL][logger]][18048] <UID: 59a261af8f3d40b9847c2b8f4262d8ba>\n",
      "Exception in callback AsyncIOEventEmitter._emit_run.<locals>._callback(<Task finishe...b8f4262d8ba>)>) at C:\\Users\\21355\\Anaconda3\\envs\\pysyft\\lib\\site-packages\\pyee\\_asyncio.py:55\n",
      "handle: <Handle AsyncIOEventEmitter._emit_run.<locals>._callback(<Task finishe...b8f4262d8ba>)>) at C:\\Users\\21355\\Anaconda3\\envs\\pysyft\\lib\\site-packages\\pyee\\_asyncio.py:55>\n",
      "Traceback (most recent call last):\n",
      "  File \"C:\\Users\\21355\\Anaconda3\\envs\\pysyft\\lib\\asyncio\\events.py\", line 80, in _run\n",
      "    self._context.run(self._callback, *self._args)\n",
      "  File \"C:\\Users\\21355\\Anaconda3\\envs\\pysyft\\lib\\site-packages\\pyee\\_asyncio.py\", line 62, in _callback\n",
      "    self.emit('error', exc)\n",
      "  File \"C:\\Users\\21355\\Anaconda3\\envs\\pysyft\\lib\\site-packages\\pyee\\_base.py\", line 116, in emit\n",
      "    self._emit_handle_potential_error(event, args[0] if args else None)\n",
      "  File \"C:\\Users\\21355\\Anaconda3\\envs\\pysyft\\lib\\site-packages\\pyee\\_base.py\", line 86, in _emit_handle_potential_error\n",
      "    raise error\n",
      "  File \"C:\\Users\\21355\\Anaconda3\\envs\\pysyft\\lib\\asyncio\\tasks.py\", line 256, in __step\n",
      "    result = coro.send(None)\n",
      "  File \"C:\\Users\\21355\\Anaconda3\\envs\\pysyft\\lib\\site-packages\\syft\\grid\\connections\\webrtc.py\", line 233, in on_message\n",
      "    await self.consumer(msg=message)\n",
      "  File \"C:\\Users\\21355\\Anaconda3\\envs\\pysyft\\lib\\site-packages\\syft\\grid\\connections\\webrtc.py\", line 449, in consumer\n",
      "    traceback_and_raise(e)\n",
      "  File \"C:\\Users\\21355\\Anaconda3\\envs\\pysyft\\lib\\site-packages\\syft\\logger.py\", line 61, in traceback_and_raise\n",
      "    raise e\n",
      "  File \"C:\\Users\\21355\\Anaconda3\\envs\\pysyft\\lib\\site-packages\\syft\\grid\\connections\\webrtc.py\", line 434, in consumer\n",
      "    self.recv_immediate_msg_without_reply(msg=_msg)\n",
      "  File \"C:\\Users\\21355\\Anaconda3\\envs\\pysyft\\lib\\site-packages\\syft\\grid\\connections\\webrtc.py\", line 490, in recv_immediate_msg_without_reply\n",
      "    traceback_and_raise(e)\n",
      "  File \"C:\\Users\\21355\\Anaconda3\\envs\\pysyft\\lib\\site-packages\\syft\\logger.py\", line 61, in traceback_and_raise\n",
      "    raise e\n",
      "  File \"C:\\Users\\21355\\Anaconda3\\envs\\pysyft\\lib\\site-packages\\syft\\grid\\connections\\webrtc.py\", line 485, in recv_immediate_msg_without_reply\n",
      "    self.node.recv_immediate_msg_without_reply(msg=msg)\n",
      "  File \"C:\\Users\\21355\\Anaconda3\\envs\\pysyft\\lib\\site-packages\\syft\\core\\node\\common\\node.py\", line 399, in recv_immediate_msg_without_reply\n",
      "    self.process_message(msg=msg, router=self.immediate_msg_without_reply_router)\n",
      "  File \"C:\\Users\\21355\\Anaconda3\\envs\\pysyft\\lib\\site-packages\\syft\\core\\node\\common\\node.py\", line 481, in process_message\n",
      "    result = service.process(\n",
      "  File \"C:\\Users\\21355\\Anaconda3\\envs\\pysyft\\lib\\site-packages\\syft\\core\\node\\common\\service\\obj_action_service.py\", line 27, in process\n",
      "    msg.execute_action(node=node, verify_key=verify_key)\n",
      "  File \"C:\\Users\\21355\\Anaconda3\\envs\\pysyft\\lib\\site-packages\\syft\\core\\node\\common\\action\\function_or_constructor_action.py\", line 94, in execute_action\n",
      "    r_arg = node.store[arg.id_at_location]\n",
      "  File \"C:\\Users\\21355\\Anaconda3\\envs\\pysyft\\lib\\site-packages\\syft\\core\\store\\store_memory.py\", line 66, in __getitem__\n",
      "    traceback_and_raise(e)\n",
      "  File \"C:\\Users\\21355\\Anaconda3\\envs\\pysyft\\lib\\site-packages\\syft\\logger.py\", line 61, in traceback_and_raise\n",
      "    raise e\n",
      "  File \"C:\\Users\\21355\\Anaconda3\\envs\\pysyft\\lib\\site-packages\\syft\\core\\store\\store_memory.py\", line 63, in __getitem__\n",
      "    return self._objects[key]\n",
      "KeyError: <UID: 59a261af8f3d40b9847c2b8f4262d8ba>\n",
      "[2021-08-09T18:39:43.083042+0100][CRITICAL][logger]][18048] <class 'syft.core.store.store_memory.MemoryStore'> __delitem__ error <UID: 59a261af8f3d40b9847c2b8f4262d8ba>.\n",
      "[2021-08-09T18:39:43.091045+0100][CRITICAL][logger]][18048] <class 'syft.core.store.store_memory.MemoryStore'> __delitem__ error <UID: aff212337ae94f38a7678fc7434de78c>.\n",
      "[2021-08-09T18:39:43.100149+0100][CRITICAL][logger]][18048] <class 'syft.core.store.store_memory.MemoryStore'> __getitem__ error <UID: fbfc33e72e1942549857104079185a46> <UID: fbfc33e72e1942549857104079185a46>\n",
      "[2021-08-09T18:39:43.101275+0100][CRITICAL][logger]][18048] <UID: fbfc33e72e1942549857104079185a46>\n",
      "[2021-08-09T18:39:43.103277+0100][CRITICAL][logger]][18048] <UID: fbfc33e72e1942549857104079185a46>\n",
      "[2021-08-09T18:39:43.104614+0100][CRITICAL][logger]][18048] <UID: fbfc33e72e1942549857104079185a46>\n"
     ]
    },
    {
     "name": "stderr",
     "output_type": "stream",
     "text": [
      "Exception in callback AsyncIOEventEmitter._emit_run.<locals>._callback(<Task finishe...04079185a46>)>) at C:\\Users\\21355\\Anaconda3\\envs\\pysyft\\lib\\site-packages\\pyee\\_asyncio.py:55\n",
      "handle: <Handle AsyncIOEventEmitter._emit_run.<locals>._callback(<Task finishe...04079185a46>)>) at C:\\Users\\21355\\Anaconda3\\envs\\pysyft\\lib\\site-packages\\pyee\\_asyncio.py:55>\n",
      "Traceback (most recent call last):\n",
      "  File \"C:\\Users\\21355\\Anaconda3\\envs\\pysyft\\lib\\asyncio\\events.py\", line 80, in _run\n",
      "    self._context.run(self._callback, *self._args)\n",
      "  File \"C:\\Users\\21355\\Anaconda3\\envs\\pysyft\\lib\\site-packages\\pyee\\_asyncio.py\", line 62, in _callback\n",
      "    self.emit('error', exc)\n",
      "  File \"C:\\Users\\21355\\Anaconda3\\envs\\pysyft\\lib\\site-packages\\pyee\\_base.py\", line 116, in emit\n",
      "    self._emit_handle_potential_error(event, args[0] if args else None)\n",
      "  File \"C:\\Users\\21355\\Anaconda3\\envs\\pysyft\\lib\\site-packages\\pyee\\_base.py\", line 86, in _emit_handle_potential_error\n",
      "    raise error\n",
      "  File \"C:\\Users\\21355\\Anaconda3\\envs\\pysyft\\lib\\asyncio\\tasks.py\", line 256, in __step\n",
      "    result = coro.send(None)\n",
      "  File \"C:\\Users\\21355\\Anaconda3\\envs\\pysyft\\lib\\site-packages\\syft\\grid\\connections\\webrtc.py\", line 233, in on_message\n",
      "    await self.consumer(msg=message)\n",
      "  File \"C:\\Users\\21355\\Anaconda3\\envs\\pysyft\\lib\\site-packages\\syft\\grid\\connections\\webrtc.py\", line 449, in consumer\n",
      "    traceback_and_raise(e)\n",
      "  File \"C:\\Users\\21355\\Anaconda3\\envs\\pysyft\\lib\\site-packages\\syft\\logger.py\", line 61, in traceback_and_raise\n",
      "    raise e\n",
      "  File \"C:\\Users\\21355\\Anaconda3\\envs\\pysyft\\lib\\site-packages\\syft\\grid\\connections\\webrtc.py\", line 434, in consumer\n",
      "    self.recv_immediate_msg_without_reply(msg=_msg)\n",
      "  File \"C:\\Users\\21355\\Anaconda3\\envs\\pysyft\\lib\\site-packages\\syft\\grid\\connections\\webrtc.py\", line 490, in recv_immediate_msg_without_reply\n",
      "    traceback_and_raise(e)\n",
      "  File \"C:\\Users\\21355\\Anaconda3\\envs\\pysyft\\lib\\site-packages\\syft\\logger.py\", line 61, in traceback_and_raise\n",
      "    raise e\n",
      "  File \"C:\\Users\\21355\\Anaconda3\\envs\\pysyft\\lib\\site-packages\\syft\\grid\\connections\\webrtc.py\", line 485, in recv_immediate_msg_without_reply\n",
      "    self.node.recv_immediate_msg_without_reply(msg=msg)\n",
      "  File \"C:\\Users\\21355\\Anaconda3\\envs\\pysyft\\lib\\site-packages\\syft\\core\\node\\common\\node.py\", line 399, in recv_immediate_msg_without_reply\n",
      "    self.process_message(msg=msg, router=self.immediate_msg_without_reply_router)\n",
      "  File \"C:\\Users\\21355\\Anaconda3\\envs\\pysyft\\lib\\site-packages\\syft\\core\\node\\common\\node.py\", line 481, in process_message\n",
      "    result = service.process(\n",
      "  File \"C:\\Users\\21355\\Anaconda3\\envs\\pysyft\\lib\\site-packages\\syft\\core\\node\\common\\service\\obj_action_service.py\", line 27, in process\n",
      "    msg.execute_action(node=node, verify_key=verify_key)\n",
      "  File \"C:\\Users\\21355\\Anaconda3\\envs\\pysyft\\lib\\site-packages\\syft\\core\\node\\common\\action\\function_or_constructor_action.py\", line 94, in execute_action\n",
      "    r_arg = node.store[arg.id_at_location]\n",
      "  File \"C:\\Users\\21355\\Anaconda3\\envs\\pysyft\\lib\\site-packages\\syft\\core\\store\\store_memory.py\", line 66, in __getitem__\n",
      "    traceback_and_raise(e)\n",
      "  File \"C:\\Users\\21355\\Anaconda3\\envs\\pysyft\\lib\\site-packages\\syft\\logger.py\", line 61, in traceback_and_raise\n",
      "    raise e\n",
      "  File \"C:\\Users\\21355\\Anaconda3\\envs\\pysyft\\lib\\site-packages\\syft\\core\\store\\store_memory.py\", line 63, in __getitem__\n",
      "    return self._objects[key]\n",
      "KeyError: <UID: fbfc33e72e1942549857104079185a46>\n",
      "[2021-08-09T18:39:43.114846+0100][CRITICAL][logger]][18048] execute_action on torch.Tensor.item failed due to missing object at: <UID: 288b616828b14e108a0403235e2c596c>\n",
      "[2021-08-09T18:39:43.119148+0100][CRITICAL][logger]][18048] <class 'syft.core.store.store_memory.MemoryStore'> __getitem__ error <UID: 16442e3624f642c1a6cd74938e4b3a06> <UID: 16442e3624f642c1a6cd74938e4b3a06>\n",
      "[2021-08-09T18:39:43.119844+0100][CRITICAL][logger]][18048] <UID: 16442e3624f642c1a6cd74938e4b3a06>\n",
      "[2021-08-09T18:39:43.120386+0100][CRITICAL][logger]][18048] <UID: 16442e3624f642c1a6cd74938e4b3a06>\n",
      "[2021-08-09T18:39:43.121528+0100][CRITICAL][logger]][18048] <UID: 16442e3624f642c1a6cd74938e4b3a06>\n",
      "Exception in callback AsyncIOEventEmitter._emit_run.<locals>._callback(<Task finishe...4938e4b3a06>)>) at C:\\Users\\21355\\Anaconda3\\envs\\pysyft\\lib\\site-packages\\pyee\\_asyncio.py:55\n",
      "handle: <Handle AsyncIOEventEmitter._emit_run.<locals>._callback(<Task finishe...4938e4b3a06>)>) at C:\\Users\\21355\\Anaconda3\\envs\\pysyft\\lib\\site-packages\\pyee\\_asyncio.py:55>\n",
      "Traceback (most recent call last):\n",
      "  File \"C:\\Users\\21355\\Anaconda3\\envs\\pysyft\\lib\\asyncio\\events.py\", line 80, in _run\n",
      "    self._context.run(self._callback, *self._args)\n",
      "  File \"C:\\Users\\21355\\Anaconda3\\envs\\pysyft\\lib\\site-packages\\pyee\\_asyncio.py\", line 62, in _callback\n",
      "    self.emit('error', exc)\n",
      "  File \"C:\\Users\\21355\\Anaconda3\\envs\\pysyft\\lib\\site-packages\\pyee\\_base.py\", line 116, in emit\n",
      "    self._emit_handle_potential_error(event, args[0] if args else None)\n",
      "  File \"C:\\Users\\21355\\Anaconda3\\envs\\pysyft\\lib\\site-packages\\pyee\\_base.py\", line 86, in _emit_handle_potential_error\n",
      "    raise error\n",
      "  File \"C:\\Users\\21355\\Anaconda3\\envs\\pysyft\\lib\\asyncio\\tasks.py\", line 256, in __step\n",
      "    result = coro.send(None)\n",
      "  File \"C:\\Users\\21355\\Anaconda3\\envs\\pysyft\\lib\\site-packages\\syft\\grid\\connections\\webrtc.py\", line 233, in on_message\n",
      "    await self.consumer(msg=message)\n",
      "  File \"C:\\Users\\21355\\Anaconda3\\envs\\pysyft\\lib\\site-packages\\syft\\grid\\connections\\webrtc.py\", line 449, in consumer\n",
      "    traceback_and_raise(e)\n",
      "  File \"C:\\Users\\21355\\Anaconda3\\envs\\pysyft\\lib\\site-packages\\syft\\logger.py\", line 61, in traceback_and_raise\n",
      "    raise e\n",
      "  File \"C:\\Users\\21355\\Anaconda3\\envs\\pysyft\\lib\\site-packages\\syft\\grid\\connections\\webrtc.py\", line 434, in consumer\n",
      "    self.recv_immediate_msg_without_reply(msg=_msg)\n",
      "  File \"C:\\Users\\21355\\Anaconda3\\envs\\pysyft\\lib\\site-packages\\syft\\grid\\connections\\webrtc.py\", line 490, in recv_immediate_msg_without_reply\n",
      "    traceback_and_raise(e)\n",
      "  File \"C:\\Users\\21355\\Anaconda3\\envs\\pysyft\\lib\\site-packages\\syft\\logger.py\", line 61, in traceback_and_raise\n",
      "    raise e\n",
      "  File \"C:\\Users\\21355\\Anaconda3\\envs\\pysyft\\lib\\site-packages\\syft\\grid\\connections\\webrtc.py\", line 485, in recv_immediate_msg_without_reply\n",
      "    self.node.recv_immediate_msg_without_reply(msg=msg)\n",
      "  File \"C:\\Users\\21355\\Anaconda3\\envs\\pysyft\\lib\\site-packages\\syft\\core\\node\\common\\node.py\", line 399, in recv_immediate_msg_without_reply\n",
      "    self.process_message(msg=msg, router=self.immediate_msg_without_reply_router)\n",
      "  File \"C:\\Users\\21355\\Anaconda3\\envs\\pysyft\\lib\\site-packages\\syft\\core\\node\\common\\node.py\", line 481, in process_message\n",
      "    result = service.process(\n",
      "  File \"C:\\Users\\21355\\Anaconda3\\envs\\pysyft\\lib\\site-packages\\syft\\core\\node\\domain\\service\\request_message.py\", line 222, in process\n",
      "    msg.object_tags.extend(node.store[msg.object_id]._tags)\n",
      "  File \"C:\\Users\\21355\\Anaconda3\\envs\\pysyft\\lib\\site-packages\\syft\\core\\store\\store_memory.py\", line 66, in __getitem__\n",
      "    traceback_and_raise(e)\n",
      "  File \"C:\\Users\\21355\\Anaconda3\\envs\\pysyft\\lib\\site-packages\\syft\\logger.py\", line 61, in traceback_and_raise\n",
      "    raise e\n",
      "  File \"C:\\Users\\21355\\Anaconda3\\envs\\pysyft\\lib\\site-packages\\syft\\core\\store\\store_memory.py\", line 63, in __getitem__\n",
      "    return self._objects[key]\n",
      "KeyError: <UID: 16442e3624f642c1a6cd74938e4b3a06>\n",
      "[2021-08-09T18:39:43.149741+0100][CRITICAL][logger]][18048] execute_action on torch.Tensor.backward failed due to missing object at: <UID: 288b616828b14e108a0403235e2c596c>\n",
      "[2021-08-09T18:39:43.156329+0100][CRITICAL][logger]][18048] <class 'syft.core.store.store_memory.MemoryStore'> __delitem__ error <UID: e5419920307140b1b636da82d420e481>.\n",
      "[2021-08-09T18:39:43.185377+0100][CRITICAL][logger]][18048] <class 'syft.core.store.store_memory.MemoryStore'> __delitem__ error <UID: fbfc33e72e1942549857104079185a46>.\n",
      "[2021-08-09T18:39:43.198022+0100][CRITICAL][logger]][18048] <class 'syft.core.store.store_memory.MemoryStore'> __delitem__ error <UID: 288b616828b14e108a0403235e2c596c>.\n",
      "[2021-08-09T18:39:43.201900+0100][CRITICAL][logger]][18048] <class 'syft.core.store.store_memory.MemoryStore'> __delitem__ error <UID: 16442e3624f642c1a6cd74938e4b3a06>.\n"
     ]
    }
   ],
   "source": [
    "duet.requests.add_handler(action=\"accept\")"
   ]
  },
  {
   "cell_type": "code",
   "execution_count": 45,
   "id": "91ce842b",
   "metadata": {},
   "outputs": [
    {
     "data": {
      "text/html": [
       "<div>\n",
       "<style scoped>\n",
       "    .dataframe tbody tr th:only-of-type {\n",
       "        vertical-align: middle;\n",
       "    }\n",
       "\n",
       "    .dataframe tbody tr th {\n",
       "        vertical-align: top;\n",
       "    }\n",
       "\n",
       "    .dataframe thead th {\n",
       "        text-align: right;\n",
       "    }\n",
       "</style>\n",
       "<table border=\"1\" class=\"dataframe\">\n",
       "  <thead>\n",
       "    <tr style=\"text-align: right;\">\n",
       "      <th></th>\n",
       "      <th>ID</th>\n",
       "      <th>Tags</th>\n",
       "      <th>Description</th>\n",
       "      <th>object_type</th>\n",
       "    </tr>\n",
       "  </thead>\n",
       "  <tbody>\n",
       "    <tr>\n",
       "      <th>0</th>\n",
       "      <td>&lt;UID: 9086c8694d384ecf837931ae00d56bf5&gt;</td>\n",
       "      <td>[]</td>\n",
       "      <td></td>\n",
       "      <td>&lt;class 'torch.Tensor'&gt;</td>\n",
       "    </tr>\n",
       "    <tr>\n",
       "      <th>1</th>\n",
       "      <td>&lt;UID: 53661b26c6c340a186de8fe76ca67ef9&gt;</td>\n",
       "      <td>[]</td>\n",
       "      <td></td>\n",
       "      <td>&lt;class 'torch.Tensor'&gt;</td>\n",
       "    </tr>\n",
       "  </tbody>\n",
       "</table>\n",
       "</div>"
      ],
      "text/plain": [
       "                                        ID Tags Description  \\\n",
       "0  <UID: 9086c8694d384ecf837931ae00d56bf5>   []               \n",
       "1  <UID: 53661b26c6c340a186de8fe76ca67ef9>   []               \n",
       "\n",
       "              object_type  \n",
       "0  <class 'torch.Tensor'>  \n",
       "1  <class 'torch.Tensor'>  "
      ]
     },
     "execution_count": 45,
     "metadata": {},
     "output_type": "execute_result"
    }
   ],
   "source": [
    "duet.store.pandas"
   ]
  },
  {
   "cell_type": "code",
   "execution_count": 50,
   "id": "ad1e3482",
   "metadata": {},
   "outputs": [
    {
     "data": {
      "text/plain": [
       "[]"
      ]
     },
     "execution_count": 50,
     "metadata": {},
     "output_type": "execute_result"
    }
   ],
   "source": [
    "duet.requests"
   ]
  },
  {
   "cell_type": "code",
   "execution_count": null,
   "id": "ff1797a6",
   "metadata": {},
   "outputs": [],
   "source": []
  }
 ],
 "metadata": {
  "kernelspec": {
   "display_name": "Python 3",
   "language": "python",
   "name": "python3"
  },
  "language_info": {
   "codemirror_mode": {
    "name": "ipython",
    "version": 3
   },
   "file_extension": ".py",
   "mimetype": "text/x-python",
   "name": "python",
   "nbconvert_exporter": "python",
   "pygments_lexer": "ipython3",
   "version": "3.9.6"
  }
 },
 "nbformat": 4,
 "nbformat_minor": 5
}
